2025-08-09 14:23:20,101 - services.quiz_scheduler - INFO - Setting up quiz schedule...
2025-08-09 14:23:20,101 - services.quiz_scheduler - INFO - Quiz scheduled at 12:00
2025-08-09 14:23:20,101 - services.quiz_scheduler - INFO - Quiz scheduled at 16:00
2025-08-09 14:23:20,101 - services.quiz_scheduler - INFO - Quiz scheduled at 20:00
2025-08-09 14:23:20,101 - __main__ - ERROR - JSON file not found: assets/data/char.json
2025-08-09 14:23:20,101 - __main__ - ERROR - JSON file not found: assets/data/plot.json
2025-08-09 14:23:20,101 - __main__ - ERROR - JSON file not found: assets/data/shop.json
2025-08-09 14:23:20,101 - __main__ - ERROR - JSON file not found: assets/data/statuetki.json
2025-08-09 14:23:20,102 - __main__ - INFO - Bot initialized successfully
2025-08-09 14:23:20,102 - __main__ - INFO - Setting up handlers...
2025-08-09 14:23:20,102 - __main__ - INFO - Starting quiz scheduler...
2025-08-09 14:23:20,102 - services.quiz_scheduler - INFO - Quiz scheduler started
2025-08-09 14:23:20,102 - __main__ - INFO - Starting bot polling...
2025-08-09 14:23:23,876 - TeleBot - ERROR - Threaded polling exception: A request to the Telegram API was unsuccessful. Error code: 409. Description: Conflict: terminated by other getUpdates request; make sure that only one bot instance is running
2025-08-09 14:23:23,877 - TeleBot - ERROR - Exception traceback:
Traceback (most recent call last):
  File "/home/spedymax/venv/lib/python3.11/site-packages/telebot/__init__.py", line 1073, in __threaded_polling
    polling_thread.raise_exceptions()
  File "/home/spedymax/venv/lib/python3.11/site-packages/telebot/util.py", line 108, in raise_exceptions
    raise self.exception_info
  File "/home/spedymax/venv/lib/python3.11/site-packages/telebot/util.py", line 90, in run
    task(*args, **kwargs)
  File "/home/spedymax/venv/lib/python3.11/site-packages/telebot/__init__.py", line 649, in __retrieve_updates
    updates = self.get_updates(offset=(self.last_update_id + 1),
             ^^^^^^^^^^^^^^^^^^^^^^^^^^^^^^^^^^^^^^^^^^^^^^^^^^
  File "/home/spedymax/venv/lib/python3.11/site-packages/telebot/__init__.py", line 623, in get_updates
    json_updates = apihelper.get_updates(self.token, offset, limit, timeout, allowed_updates, long_polling_timeout)
                   ^^^^^^^^^^^^^^^^^^^^^^^^^^^^^^^^^^^^^^^^^^^^^^^^^^^^^^^^^^^^^^^^^^^^^^^^^^^^^^^^^^^^^^^^^^^^^^^^
  File "/home/spedymax/venv/lib/python3.11/site-packages/telebot/apihelper.py", line 321, in get_updates
    return _make_request(token, method_url, params=payload)
           ^^^^^^^^^^^^^^^^^^^^^^^^^^^^^^^^^^^^^^^^^^^^^^^^
  File "/home/spedymax/venv/lib/python3.11/site-packages/telebot/apihelper.py", line 162, in _make_request
    json_result = _check_result(method_name, result)
                  ^^^^^^^^^^^^^^^^^^^^^^^^^^^^^^^^^^
  File "/home/spedymax/venv/lib/python3.11/site-packages/telebot/apihelper.py", line 189, in _check_result
    raise ApiTelegramException(method_name, result, result_json)
telebot.apihelper.ApiTelegramException: A request to the Telegram API was unsuccessful. Error code: 409. Description: Conflict: terminated by other getUpdates request; make sure that only one bot instance is running

2025-08-09 14:23:27,740 - TeleBot - ERROR - Threaded polling exception: A request to the Telegram API was unsuccessful. Error code: 409. Description: Conflict: terminated by other getUpdates request; make sure that only one bot instance is running
2025-08-09 14:23:27,740 - TeleBot - ERROR - Exception traceback:
Traceback (most recent call last):
  File "/home/spedymax/venv/lib/python3.11/site-packages/telebot/__init__.py", line 1073, in __threaded_polling
    polling_thread.raise_exceptions()
  File "/home/spedymax/venv/lib/python3.11/site-packages/telebot/util.py", line 108, in raise_exceptions
    raise self.exception_info
  File "/home/spedymax/venv/lib/python3.11/site-packages/telebot/util.py", line 90, in run
    task(*args, **kwargs)
  File "/home/spedymax/venv/lib/python3.11/site-packages/telebot/__init__.py", line 649, in __retrieve_updates
    updates = self.get_updates(offset=(self.last_update_id + 1),
             ^^^^^^^^^^^^^^^^^^^^^^^^^^^^^^^^^^^^^^^^^^^^^^^^^^
  File "/home/spedymax/venv/lib/python3.11/site-packages/telebot/__init__.py", line 623, in get_updates
    json_updates = apihelper.get_updates(self.token, offset, limit, timeout, allowed_updates, long_polling_timeout)
                   ^^^^^^^^^^^^^^^^^^^^^^^^^^^^^^^^^^^^^^^^^^^^^^^^^^^^^^^^^^^^^^^^^^^^^^^^^^^^^^^^^^^^^^^^^^^^^^^^
  File "/home/spedymax/venv/lib/python3.11/site-packages/telebot/apihelper.py", line 321, in get_updates
    return _make_request(token, method_url, params=payload)
           ^^^^^^^^^^^^^^^^^^^^^^^^^^^^^^^^^^^^^^^^^^^^^^^^
  File "/home/spedymax/venv/lib/python3.11/site-packages/telebot/apihelper.py", line 162, in _make_request
    json_result = _check_result(method_name, result)
                  ^^^^^^^^^^^^^^^^^^^^^^^^^^^^^^^^^^
  File "/home/spedymax/venv/lib/python3.11/site-packages/telebot/apihelper.py", line 189, in _check_result
    raise ApiTelegramException(method_name, result, result_json)
telebot.apihelper.ApiTelegramException: A request to the Telegram API was unsuccessful. Error code: 409. Description: Conflict: terminated by other getUpdates request; make sure that only one bot instance is running

2025-08-09 14:23:32,338 - TeleBot - ERROR - Threaded polling exception: A request to the Telegram API was unsuccessful. Error code: 409. Description: Conflict: terminated by other getUpdates request; make sure that only one bot instance is running
2025-08-09 14:23:32,340 - TeleBot - ERROR - Exception traceback:
Traceback (most recent call last):
  File "/home/spedymax/venv/lib/python3.11/site-packages/telebot/__init__.py", line 1073, in __threaded_polling
    polling_thread.raise_exceptions()
  File "/home/spedymax/venv/lib/python3.11/site-packages/telebot/util.py", line 108, in raise_exceptions
    raise self.exception_info
  File "/home/spedymax/venv/lib/python3.11/site-packages/telebot/util.py", line 90, in run
    task(*args, **kwargs)
  File "/home/spedymax/venv/lib/python3.11/site-packages/telebot/__init__.py", line 649, in __retrieve_updates
    updates = self.get_updates(offset=(self.last_update_id + 1),
             ^^^^^^^^^^^^^^^^^^^^^^^^^^^^^^^^^^^^^^^^^^^^^^^^^^
  File "/home/spedymax/venv/lib/python3.11/site-packages/telebot/__init__.py", line 623, in get_updates
    json_updates = apihelper.get_updates(self.token, offset, limit, timeout, allowed_updates, long_polling_timeout)
                   ^^^^^^^^^^^^^^^^^^^^^^^^^^^^^^^^^^^^^^^^^^^^^^^^^^^^^^^^^^^^^^^^^^^^^^^^^^^^^^^^^^^^^^^^^^^^^^^^
  File "/home/spedymax/venv/lib/python3.11/site-packages/telebot/apihelper.py", line 321, in get_updates
    return _make_request(token, method_url, params=payload)
           ^^^^^^^^^^^^^^^^^^^^^^^^^^^^^^^^^^^^^^^^^^^^^^^^
  File "/home/spedymax/venv/lib/python3.11/site-packages/telebot/apihelper.py", line 162, in _make_request
    json_result = _check_result(method_name, result)
                  ^^^^^^^^^^^^^^^^^^^^^^^^^^^^^^^^^^
  File "/home/spedymax/venv/lib/python3.11/site-packages/telebot/apihelper.py", line 189, in _check_result
    raise ApiTelegramException(method_name, result, result_json)
telebot.apihelper.ApiTelegramException: A request to the Telegram API was unsuccessful. Error code: 409. Description: Conflict: terminated by other getUpdates request; make sure that only one bot instance is running

2025-08-09 14:23:38,432 - TeleBot - ERROR - Threaded polling exception: A request to the Telegram API was unsuccessful. Error code: 409. Description: Conflict: terminated by other getUpdates request; make sure that only one bot instance is running
2025-08-09 14:23:38,433 - TeleBot - ERROR - Exception traceback:
Traceback (most recent call last):
  File "/home/spedymax/venv/lib/python3.11/site-packages/telebot/__init__.py", line 1073, in __threaded_polling
    polling_thread.raise_exceptions()
  File "/home/spedymax/venv/lib/python3.11/site-packages/telebot/util.py", line 108, in raise_exceptions
    raise self.exception_info
  File "/home/spedymax/venv/lib/python3.11/site-packages/telebot/util.py", line 90, in run
    task(*args, **kwargs)
  File "/home/spedymax/venv/lib/python3.11/site-packages/telebot/__init__.py", line 649, in __retrieve_updates
    updates = self.get_updates(offset=(self.last_update_id + 1),
             ^^^^^^^^^^^^^^^^^^^^^^^^^^^^^^^^^^^^^^^^^^^^^^^^^^
  File "/home/spedymax/venv/lib/python3.11/site-packages/telebot/__init__.py", line 623, in get_updates
    json_updates = apihelper.get_updates(self.token, offset, limit, timeout, allowed_updates, long_polling_timeout)
                   ^^^^^^^^^^^^^^^^^^^^^^^^^^^^^^^^^^^^^^^^^^^^^^^^^^^^^^^^^^^^^^^^^^^^^^^^^^^^^^^^^^^^^^^^^^^^^^^^
  File "/home/spedymax/venv/lib/python3.11/site-packages/telebot/apihelper.py", line 321, in get_updates
    return _make_request(token, method_url, params=payload)
           ^^^^^^^^^^^^^^^^^^^^^^^^^^^^^^^^^^^^^^^^^^^^^^^^
  File "/home/spedymax/venv/lib/python3.11/site-packages/telebot/apihelper.py", line 162, in _make_request
    json_result = _check_result(method_name, result)
                  ^^^^^^^^^^^^^^^^^^^^^^^^^^^^^^^^^^
  File "/home/spedymax/venv/lib/python3.11/site-packages/telebot/apihelper.py", line 189, in _check_result
    raise ApiTelegramException(method_name, result, result_json)
telebot.apihelper.ApiTelegramException: A request to the Telegram API was unsuccessful. Error code: 409. Description: Conflict: terminated by other getUpdates request; make sure that only one bot instance is running

2025-08-09 14:23:44,559 - TeleBot - ERROR - Threaded polling exception: A request to the Telegram API was unsuccessful. Error code: 409. Description: Conflict: terminated by other getUpdates request; make sure that only one bot instance is running
2025-08-09 14:23:44,560 - TeleBot - ERROR - Exception traceback:
Traceback (most recent call last):
  File "/home/spedymax/venv/lib/python3.11/site-packages/telebot/__init__.py", line 1073, in __threaded_polling
    polling_thread.raise_exceptions()
  File "/home/spedymax/venv/lib/python3.11/site-packages/telebot/util.py", line 108, in raise_exceptions
    raise self.exception_info
  File "/home/spedymax/venv/lib/python3.11/site-packages/telebot/util.py", line 90, in run
    task(*args, **kwargs)
  File "/home/spedymax/venv/lib/python3.11/site-packages/telebot/__init__.py", line 649, in __retrieve_updates
    updates = self.get_updates(offset=(self.last_update_id + 1),
             ^^^^^^^^^^^^^^^^^^^^^^^^^^^^^^^^^^^^^^^^^^^^^^^^^^
  File "/home/spedymax/venv/lib/python3.11/site-packages/telebot/__init__.py", line 623, in get_updates
    json_updates = apihelper.get_updates(self.token, offset, limit, timeout, allowed_updates, long_polling_timeout)
                   ^^^^^^^^^^^^^^^^^^^^^^^^^^^^^^^^^^^^^^^^^^^^^^^^^^^^^^^^^^^^^^^^^^^^^^^^^^^^^^^^^^^^^^^^^^^^^^^^
  File "/home/spedymax/venv/lib/python3.11/site-packages/telebot/apihelper.py", line 321, in get_updates
    return _make_request(token, method_url, params=payload)
           ^^^^^^^^^^^^^^^^^^^^^^^^^^^^^^^^^^^^^^^^^^^^^^^^
  File "/home/spedymax/venv/lib/python3.11/site-packages/telebot/apihelper.py", line 162, in _make_request
    json_result = _check_result(method_name, result)
                  ^^^^^^^^^^^^^^^^^^^^^^^^^^^^^^^^^^
  File "/home/spedymax/venv/lib/python3.11/site-packages/telebot/apihelper.py", line 189, in _check_result
    raise ApiTelegramException(method_name, result, result_json)
telebot.apihelper.ApiTelegramException: A request to the Telegram API was unsuccessful. Error code: 409. Description: Conflict: terminated by other getUpdates request; make sure that only one bot instance is running

2025-08-09 14:24:20,207 - services.quiz_scheduler - INFO - Setting up quiz schedule...
2025-08-09 14:24:20,208 - services.quiz_scheduler - INFO - Quiz scheduled at 12:00
2025-08-09 14:24:20,208 - services.quiz_scheduler - INFO - Quiz scheduled at 16:00
2025-08-09 14:24:20,208 - services.quiz_scheduler - INFO - Quiz scheduled at 20:00
2025-08-09 14:24:20,209 - __main__ - ERROR - JSON file not found: assets/data/char.json
2025-08-09 14:24:20,209 - __main__ - ERROR - JSON file not found: assets/data/plot.json
2025-08-09 14:24:20,209 - __main__ - ERROR - JSON file not found: assets/data/shop.json
2025-08-09 14:24:20,209 - __main__ - ERROR - JSON file not found: assets/data/statuetki.json
2025-08-09 14:24:20,209 - __main__ - INFO - Bot initialized successfully
2025-08-09 14:24:20,209 - __main__ - INFO - Setting up handlers...
2025-08-09 14:24:20,210 - __main__ - INFO - Starting quiz scheduler...
2025-08-09 14:24:20,211 - services.quiz_scheduler - INFO - Quiz scheduler started
2025-08-09 14:24:20,211 - __main__ - INFO - Starting bot polling...
2025-08-09 14:24:20,595 - TeleBot - ERROR - Threaded polling exception: A request to the Telegram API was unsuccessful. Error code: 409. Description: Conflict: terminated by other getUpdates request; make sure that only one bot instance is running
2025-08-09 14:24:20,598 - TeleBot - ERROR - Exception traceback:
Traceback (most recent call last):
  File "/home/spedymax/venv/lib/python3.11/site-packages/telebot/__init__.py", line 1073, in __threaded_polling
    polling_thread.raise_exceptions()
  File "/home/spedymax/venv/lib/python3.11/site-packages/telebot/util.py", line 108, in raise_exceptions
    raise self.exception_info
  File "/home/spedymax/venv/lib/python3.11/site-packages/telebot/util.py", line 90, in run
    task(*args, **kwargs)
  File "/home/spedymax/venv/lib/python3.11/site-packages/telebot/__init__.py", line 649, in __retrieve_updates
    updates = self.get_updates(offset=(self.last_update_id + 1),
             ^^^^^^^^^^^^^^^^^^^^^^^^^^^^^^^^^^^^^^^^^^^^^^^^^^
  File "/home/spedymax/venv/lib/python3.11/site-packages/telebot/__init__.py", line 623, in get_updates
    json_updates = apihelper.get_updates(self.token, offset, limit, timeout, allowed_updates, long_polling_timeout)
                   ^^^^^^^^^^^^^^^^^^^^^^^^^^^^^^^^^^^^^^^^^^^^^^^^^^^^^^^^^^^^^^^^^^^^^^^^^^^^^^^^^^^^^^^^^^^^^^^^
  File "/home/spedymax/venv/lib/python3.11/site-packages/telebot/apihelper.py", line 321, in get_updates
    return _make_request(token, method_url, params=payload)
           ^^^^^^^^^^^^^^^^^^^^^^^^^^^^^^^^^^^^^^^^^^^^^^^^
  File "/home/spedymax/venv/lib/python3.11/site-packages/telebot/apihelper.py", line 162, in _make_request
    json_result = _check_result(method_name, result)
                  ^^^^^^^^^^^^^^^^^^^^^^^^^^^^^^^^^^
  File "/home/spedymax/venv/lib/python3.11/site-packages/telebot/apihelper.py", line 189, in _check_result
    raise ApiTelegramException(method_name, result, result_json)
telebot.apihelper.ApiTelegramException: A request to the Telegram API was unsuccessful. Error code: 409. Description: Conflict: terminated by other getUpdates request; make sure that only one bot instance is running

2025-08-09 14:24:23,902 - TeleBot - ERROR - Threaded polling exception: A request to the Telegram API was unsuccessful. Error code: 409. Description: Conflict: terminated by other getUpdates request; make sure that only one bot instance is running
2025-08-09 14:24:23,905 - TeleBot - ERROR - Exception traceback:
Traceback (most recent call last):
  File "/home/spedymax/venv/lib/python3.11/site-packages/telebot/__init__.py", line 1073, in __threaded_polling
    polling_thread.raise_exceptions()
  File "/home/spedymax/venv/lib/python3.11/site-packages/telebot/util.py", line 108, in raise_exceptions
    raise self.exception_info
  File "/home/spedymax/venv/lib/python3.11/site-packages/telebot/util.py", line 90, in run
    task(*args, **kwargs)
  File "/home/spedymax/venv/lib/python3.11/site-packages/telebot/__init__.py", line 649, in __retrieve_updates
    updates = self.get_updates(offset=(self.last_update_id + 1),
             ^^^^^^^^^^^^^^^^^^^^^^^^^^^^^^^^^^^^^^^^^^^^^^^^^^
  File "/home/spedymax/venv/lib/python3.11/site-packages/telebot/__init__.py", line 623, in get_updates
    json_updates = apihelper.get_updates(self.token, offset, limit, timeout, allowed_updates, long_polling_timeout)
                   ^^^^^^^^^^^^^^^^^^^^^^^^^^^^^^^^^^^^^^^^^^^^^^^^^^^^^^^^^^^^^^^^^^^^^^^^^^^^^^^^^^^^^^^^^^^^^^^^
  File "/home/spedymax/venv/lib/python3.11/site-packages/telebot/apihelper.py", line 321, in get_updates
    return _make_request(token, method_url, params=payload)
           ^^^^^^^^^^^^^^^^^^^^^^^^^^^^^^^^^^^^^^^^^^^^^^^^
  File "/home/spedymax/venv/lib/python3.11/site-packages/telebot/apihelper.py", line 162, in _make_request
    json_result = _check_result(method_name, result)
                  ^^^^^^^^^^^^^^^^^^^^^^^^^^^^^^^^^^
  File "/home/spedymax/venv/lib/python3.11/site-packages/telebot/apihelper.py", line 189, in _check_result
    raise ApiTelegramException(method_name, result, result_json)
telebot.apihelper.ApiTelegramException: A request to the Telegram API was unsuccessful. Error code: 409. Description: Conflict: terminated by other getUpdates request; make sure that only one bot instance is running

2025-08-09 14:24:24,201 - TeleBot - ERROR - Threaded polling exception: A request to the Telegram API was unsuccessful. Error code: 409. Description: Conflict: terminated by other getUpdates request; make sure that only one bot instance is running
2025-08-09 14:24:24,202 - TeleBot - ERROR - Exception traceback:
Traceback (most recent call last):
  File "/home/spedymax/venv/lib/python3.11/site-packages/telebot/__init__.py", line 1073, in __threaded_polling
    polling_thread.raise_exceptions()
  File "/home/spedymax/venv/lib/python3.11/site-packages/telebot/util.py", line 108, in raise_exceptions
    raise self.exception_info
  File "/home/spedymax/venv/lib/python3.11/site-packages/telebot/util.py", line 90, in run
    task(*args, **kwargs)
  File "/home/spedymax/venv/lib/python3.11/site-packages/telebot/__init__.py", line 649, in __retrieve_updates
    updates = self.get_updates(offset=(self.last_update_id + 1),
             ^^^^^^^^^^^^^^^^^^^^^^^^^^^^^^^^^^^^^^^^^^^^^^^^^^
  File "/home/spedymax/venv/lib/python3.11/site-packages/telebot/__init__.py", line 623, in get_updates
    json_updates = apihelper.get_updates(self.token, offset, limit, timeout, allowed_updates, long_polling_timeout)
                   ^^^^^^^^^^^^^^^^^^^^^^^^^^^^^^^^^^^^^^^^^^^^^^^^^^^^^^^^^^^^^^^^^^^^^^^^^^^^^^^^^^^^^^^^^^^^^^^^
  File "/home/spedymax/venv/lib/python3.11/site-packages/telebot/apihelper.py", line 321, in get_updates
    return _make_request(token, method_url, params=payload)
           ^^^^^^^^^^^^^^^^^^^^^^^^^^^^^^^^^^^^^^^^^^^^^^^^
  File "/home/spedymax/venv/lib/python3.11/site-packages/telebot/apihelper.py", line 162, in _make_request
    json_result = _check_result(method_name, result)
                  ^^^^^^^^^^^^^^^^^^^^^^^^^^^^^^^^^^
  File "/home/spedymax/venv/lib/python3.11/site-packages/telebot/apihelper.py", line 189, in _check_result
    raise ApiTelegramException(method_name, result, result_json)
telebot.apihelper.ApiTelegramException: A request to the Telegram API was unsuccessful. Error code: 409. Description: Conflict: terminated by other getUpdates request; make sure that only one bot instance is running

2025-08-09 14:24:27,759 - TeleBot - ERROR - Threaded polling exception: A request to the Telegram API was unsuccessful. Error code: 409. Description: Conflict: terminated by other getUpdates request; make sure that only one bot instance is running
2025-08-09 14:24:27,761 - TeleBot - ERROR - Exception traceback:
Traceback (most recent call last):
  File "/home/spedymax/venv/lib/python3.11/site-packages/telebot/__init__.py", line 1073, in __threaded_polling
    polling_thread.raise_exceptions()
  File "/home/spedymax/venv/lib/python3.11/site-packages/telebot/util.py", line 108, in raise_exceptions
    raise self.exception_info
  File "/home/spedymax/venv/lib/python3.11/site-packages/telebot/util.py", line 90, in run
    task(*args, **kwargs)
  File "/home/spedymax/venv/lib/python3.11/site-packages/telebot/__init__.py", line 649, in __retrieve_updates
    updates = self.get_updates(offset=(self.last_update_id + 1),
             ^^^^^^^^^^^^^^^^^^^^^^^^^^^^^^^^^^^^^^^^^^^^^^^^^^
  File "/home/spedymax/venv/lib/python3.11/site-packages/telebot/__init__.py", line 623, in get_updates
    json_updates = apihelper.get_updates(self.token, offset, limit, timeout, allowed_updates, long_polling_timeout)
                   ^^^^^^^^^^^^^^^^^^^^^^^^^^^^^^^^^^^^^^^^^^^^^^^^^^^^^^^^^^^^^^^^^^^^^^^^^^^^^^^^^^^^^^^^^^^^^^^^
  File "/home/spedymax/venv/lib/python3.11/site-packages/telebot/apihelper.py", line 321, in get_updates
    return _make_request(token, method_url, params=payload)
           ^^^^^^^^^^^^^^^^^^^^^^^^^^^^^^^^^^^^^^^^^^^^^^^^
  File "/home/spedymax/venv/lib/python3.11/site-packages/telebot/apihelper.py", line 162, in _make_request
    json_result = _check_result(method_name, result)
                  ^^^^^^^^^^^^^^^^^^^^^^^^^^^^^^^^^^
  File "/home/spedymax/venv/lib/python3.11/site-packages/telebot/apihelper.py", line 189, in _check_result
    raise ApiTelegramException(method_name, result, result_json)
telebot.apihelper.ApiTelegramException: A request to the Telegram API was unsuccessful. Error code: 409. Description: Conflict: terminated by other getUpdates request; make sure that only one bot instance is running

2025-08-09 14:24:28,346 - TeleBot - ERROR - Threaded polling exception: A request to the Telegram API was unsuccessful. Error code: 409. Description: Conflict: terminated by other getUpdates request; make sure that only one bot instance is running
2025-08-09 14:24:28,347 - TeleBot - ERROR - Exception traceback:
Traceback (most recent call last):
  File "/home/spedymax/venv/lib/python3.11/site-packages/telebot/__init__.py", line 1073, in __threaded_polling
    polling_thread.raise_exceptions()
  File "/home/spedymax/venv/lib/python3.11/site-packages/telebot/util.py", line 108, in raise_exceptions
    raise self.exception_info
  File "/home/spedymax/venv/lib/python3.11/site-packages/telebot/util.py", line 90, in run
    task(*args, **kwargs)
  File "/home/spedymax/venv/lib/python3.11/site-packages/telebot/__init__.py", line 649, in __retrieve_updates
    updates = self.get_updates(offset=(self.last_update_id + 1),
             ^^^^^^^^^^^^^^^^^^^^^^^^^^^^^^^^^^^^^^^^^^^^^^^^^^
  File "/home/spedymax/venv/lib/python3.11/site-packages/telebot/__init__.py", line 623, in get_updates
    json_updates = apihelper.get_updates(self.token, offset, limit, timeout, allowed_updates, long_polling_timeout)
                   ^^^^^^^^^^^^^^^^^^^^^^^^^^^^^^^^^^^^^^^^^^^^^^^^^^^^^^^^^^^^^^^^^^^^^^^^^^^^^^^^^^^^^^^^^^^^^^^^
  File "/home/spedymax/venv/lib/python3.11/site-packages/telebot/apihelper.py", line 321, in get_updates
    return _make_request(token, method_url, params=payload)
           ^^^^^^^^^^^^^^^^^^^^^^^^^^^^^^^^^^^^^^^^^^^^^^^^
  File "/home/spedymax/venv/lib/python3.11/site-packages/telebot/apihelper.py", line 162, in _make_request
    json_result = _check_result(method_name, result)
                  ^^^^^^^^^^^^^^^^^^^^^^^^^^^^^^^^^^
  File "/home/spedymax/venv/lib/python3.11/site-packages/telebot/apihelper.py", line 189, in _check_result
    raise ApiTelegramException(method_name, result, result_json)
telebot.apihelper.ApiTelegramException: A request to the Telegram API was unsuccessful. Error code: 409. Description: Conflict: terminated by other getUpdates request; make sure that only one bot instance is running

2025-08-09 14:24:32,394 - TeleBot - ERROR - Threaded polling exception: A request to the Telegram API was unsuccessful. Error code: 409. Description: Conflict: terminated by other getUpdates request; make sure that only one bot instance is running
2025-08-09 14:24:32,395 - TeleBot - ERROR - Exception traceback:
Traceback (most recent call last):
  File "/home/spedymax/venv/lib/python3.11/site-packages/telebot/__init__.py", line 1073, in __threaded_polling
    polling_thread.raise_exceptions()
  File "/home/spedymax/venv/lib/python3.11/site-packages/telebot/util.py", line 108, in raise_exceptions
    raise self.exception_info
  File "/home/spedymax/venv/lib/python3.11/site-packages/telebot/util.py", line 90, in run
    task(*args, **kwargs)
  File "/home/spedymax/venv/lib/python3.11/site-packages/telebot/__init__.py", line 649, in __retrieve_updates
    updates = self.get_updates(offset=(self.last_update_id + 1),
             ^^^^^^^^^^^^^^^^^^^^^^^^^^^^^^^^^^^^^^^^^^^^^^^^^^
  File "/home/spedymax/venv/lib/python3.11/site-packages/telebot/__init__.py", line 623, in get_updates
    json_updates = apihelper.get_updates(self.token, offset, limit, timeout, allowed_updates, long_polling_timeout)
                   ^^^^^^^^^^^^^^^^^^^^^^^^^^^^^^^^^^^^^^^^^^^^^^^^^^^^^^^^^^^^^^^^^^^^^^^^^^^^^^^^^^^^^^^^^^^^^^^^
  File "/home/spedymax/venv/lib/python3.11/site-packages/telebot/apihelper.py", line 321, in get_updates
    return _make_request(token, method_url, params=payload)
           ^^^^^^^^^^^^^^^^^^^^^^^^^^^^^^^^^^^^^^^^^^^^^^^^
  File "/home/spedymax/venv/lib/python3.11/site-packages/telebot/apihelper.py", line 162, in _make_request
    json_result = _check_result(method_name, result)
                  ^^^^^^^^^^^^^^^^^^^^^^^^^^^^^^^^^^
  File "/home/spedymax/venv/lib/python3.11/site-packages/telebot/apihelper.py", line 189, in _check_result
    raise ApiTelegramException(method_name, result, result_json)
telebot.apihelper.ApiTelegramException: A request to the Telegram API was unsuccessful. Error code: 409. Description: Conflict: terminated by other getUpdates request; make sure that only one bot instance is running

2025-08-09 14:24:33,448 - TeleBot - ERROR - Threaded polling exception: A request to the Telegram API was unsuccessful. Error code: 409. Description: Conflict: terminated by other getUpdates request; make sure that only one bot instance is running
2025-08-09 14:24:33,448 - TeleBot - ERROR - Exception traceback:
Traceback (most recent call last):
  File "/home/spedymax/venv/lib/python3.11/site-packages/telebot/__init__.py", line 1073, in __threaded_polling
    polling_thread.raise_exceptions()
  File "/home/spedymax/venv/lib/python3.11/site-packages/telebot/util.py", line 108, in raise_exceptions
    raise self.exception_info
  File "/home/spedymax/venv/lib/python3.11/site-packages/telebot/util.py", line 90, in run
    task(*args, **kwargs)
  File "/home/spedymax/venv/lib/python3.11/site-packages/telebot/__init__.py", line 649, in __retrieve_updates
    updates = self.get_updates(offset=(self.last_update_id + 1),
             ^^^^^^^^^^^^^^^^^^^^^^^^^^^^^^^^^^^^^^^^^^^^^^^^^^
  File "/home/spedymax/venv/lib/python3.11/site-packages/telebot/__init__.py", line 623, in get_updates
    json_updates = apihelper.get_updates(self.token, offset, limit, timeout, allowed_updates, long_polling_timeout)
                   ^^^^^^^^^^^^^^^^^^^^^^^^^^^^^^^^^^^^^^^^^^^^^^^^^^^^^^^^^^^^^^^^^^^^^^^^^^^^^^^^^^^^^^^^^^^^^^^^
  File "/home/spedymax/venv/lib/python3.11/site-packages/telebot/apihelper.py", line 321, in get_updates
    return _make_request(token, method_url, params=payload)
           ^^^^^^^^^^^^^^^^^^^^^^^^^^^^^^^^^^^^^^^^^^^^^^^^
  File "/home/spedymax/venv/lib/python3.11/site-packages/telebot/apihelper.py", line 162, in _make_request
    json_result = _check_result(method_name, result)
                  ^^^^^^^^^^^^^^^^^^^^^^^^^^^^^^^^^^
  File "/home/spedymax/venv/lib/python3.11/site-packages/telebot/apihelper.py", line 189, in _check_result
    raise ApiTelegramException(method_name, result, result_json)
telebot.apihelper.ApiTelegramException: A request to the Telegram API was unsuccessful. Error code: 409. Description: Conflict: terminated by other getUpdates request; make sure that only one bot instance is running

2025-08-09 14:24:38,626 - TeleBot - ERROR - Threaded polling exception: A request to the Telegram API was unsuccessful. Error code: 409. Description: Conflict: terminated by other getUpdates request; make sure that only one bot instance is running
2025-08-09 14:24:38,627 - TeleBot - ERROR - Exception traceback:
Traceback (most recent call last):
  File "/home/spedymax/venv/lib/python3.11/site-packages/telebot/__init__.py", line 1073, in __threaded_polling
    polling_thread.raise_exceptions()
  File "/home/spedymax/venv/lib/python3.11/site-packages/telebot/util.py", line 108, in raise_exceptions
    raise self.exception_info
  File "/home/spedymax/venv/lib/python3.11/site-packages/telebot/util.py", line 90, in run
    task(*args, **kwargs)
  File "/home/spedymax/venv/lib/python3.11/site-packages/telebot/__init__.py", line 649, in __retrieve_updates
    updates = self.get_updates(offset=(self.last_update_id + 1),
             ^^^^^^^^^^^^^^^^^^^^^^^^^^^^^^^^^^^^^^^^^^^^^^^^^^
  File "/home/spedymax/venv/lib/python3.11/site-packages/telebot/__init__.py", line 623, in get_updates
    json_updates = apihelper.get_updates(self.token, offset, limit, timeout, allowed_updates, long_polling_timeout)
                   ^^^^^^^^^^^^^^^^^^^^^^^^^^^^^^^^^^^^^^^^^^^^^^^^^^^^^^^^^^^^^^^^^^^^^^^^^^^^^^^^^^^^^^^^^^^^^^^^
  File "/home/spedymax/venv/lib/python3.11/site-packages/telebot/apihelper.py", line 321, in get_updates
    return _make_request(token, method_url, params=payload)
           ^^^^^^^^^^^^^^^^^^^^^^^^^^^^^^^^^^^^^^^^^^^^^^^^
  File "/home/spedymax/venv/lib/python3.11/site-packages/telebot/apihelper.py", line 162, in _make_request
    json_result = _check_result(method_name, result)
                  ^^^^^^^^^^^^^^^^^^^^^^^^^^^^^^^^^^
  File "/home/spedymax/venv/lib/python3.11/site-packages/telebot/apihelper.py", line 189, in _check_result
    raise ApiTelegramException(method_name, result, result_json)
telebot.apihelper.ApiTelegramException: A request to the Telegram API was unsuccessful. Error code: 409. Description: Conflict: terminated by other getUpdates request; make sure that only one bot instance is running

2025-08-09 14:24:40,677 - TeleBot - ERROR - Threaded polling exception: A request to the Telegram API was unsuccessful. Error code: 409. Description: Conflict: terminated by other getUpdates request; make sure that only one bot instance is running
2025-08-09 14:24:40,678 - TeleBot - ERROR - Exception traceback:
Traceback (most recent call last):
  File "/home/spedymax/venv/lib/python3.11/site-packages/telebot/__init__.py", line 1073, in __threaded_polling
    polling_thread.raise_exceptions()
  File "/home/spedymax/venv/lib/python3.11/site-packages/telebot/util.py", line 108, in raise_exceptions
    raise self.exception_info
  File "/home/spedymax/venv/lib/python3.11/site-packages/telebot/util.py", line 90, in run
    task(*args, **kwargs)
  File "/home/spedymax/venv/lib/python3.11/site-packages/telebot/__init__.py", line 649, in __retrieve_updates
    updates = self.get_updates(offset=(self.last_update_id + 1),
             ^^^^^^^^^^^^^^^^^^^^^^^^^^^^^^^^^^^^^^^^^^^^^^^^^^
  File "/home/spedymax/venv/lib/python3.11/site-packages/telebot/__init__.py", line 623, in get_updates
    json_updates = apihelper.get_updates(self.token, offset, limit, timeout, allowed_updates, long_polling_timeout)
                   ^^^^^^^^^^^^^^^^^^^^^^^^^^^^^^^^^^^^^^^^^^^^^^^^^^^^^^^^^^^^^^^^^^^^^^^^^^^^^^^^^^^^^^^^^^^^^^^^
  File "/home/spedymax/venv/lib/python3.11/site-packages/telebot/apihelper.py", line 321, in get_updates
    return _make_request(token, method_url, params=payload)
           ^^^^^^^^^^^^^^^^^^^^^^^^^^^^^^^^^^^^^^^^^^^^^^^^
  File "/home/spedymax/venv/lib/python3.11/site-packages/telebot/apihelper.py", line 162, in _make_request
    json_result = _check_result(method_name, result)
                  ^^^^^^^^^^^^^^^^^^^^^^^^^^^^^^^^^^
  File "/home/spedymax/venv/lib/python3.11/site-packages/telebot/apihelper.py", line 189, in _check_result
    raise ApiTelegramException(method_name, result, result_json)
telebot.apihelper.ApiTelegramException: A request to the Telegram API was unsuccessful. Error code: 409. Description: Conflict: terminated by other getUpdates request; make sure that only one bot instance is running

2025-08-09 14:24:44,733 - TeleBot - ERROR - Threaded polling exception: A request to the Telegram API was unsuccessful. Error code: 409. Description: Conflict: terminated by other getUpdates request; make sure that only one bot instance is running
2025-08-09 14:24:44,734 - TeleBot - ERROR - Exception traceback:
Traceback (most recent call last):
  File "/home/spedymax/venv/lib/python3.11/site-packages/telebot/__init__.py", line 1073, in __threaded_polling
    polling_thread.raise_exceptions()
  File "/home/spedymax/venv/lib/python3.11/site-packages/telebot/util.py", line 108, in raise_exceptions
    raise self.exception_info
  File "/home/spedymax/venv/lib/python3.11/site-packages/telebot/util.py", line 90, in run
    task(*args, **kwargs)
  File "/home/spedymax/venv/lib/python3.11/site-packages/telebot/__init__.py", line 649, in __retrieve_updates
    updates = self.get_updates(offset=(self.last_update_id + 1),
             ^^^^^^^^^^^^^^^^^^^^^^^^^^^^^^^^^^^^^^^^^^^^^^^^^^
  File "/home/spedymax/venv/lib/python3.11/site-packages/telebot/__init__.py", line 623, in get_updates
    json_updates = apihelper.get_updates(self.token, offset, limit, timeout, allowed_updates, long_polling_timeout)
                   ^^^^^^^^^^^^^^^^^^^^^^^^^^^^^^^^^^^^^^^^^^^^^^^^^^^^^^^^^^^^^^^^^^^^^^^^^^^^^^^^^^^^^^^^^^^^^^^^
  File "/home/spedymax/venv/lib/python3.11/site-packages/telebot/apihelper.py", line 321, in get_updates
    return _make_request(token, method_url, params=payload)
           ^^^^^^^^^^^^^^^^^^^^^^^^^^^^^^^^^^^^^^^^^^^^^^^^
  File "/home/spedymax/venv/lib/python3.11/site-packages/telebot/apihelper.py", line 162, in _make_request
    json_result = _check_result(method_name, result)
                  ^^^^^^^^^^^^^^^^^^^^^^^^^^^^^^^^^^
  File "/home/spedymax/venv/lib/python3.11/site-packages/telebot/apihelper.py", line 189, in _check_result
    raise ApiTelegramException(method_name, result, result_json)
telebot.apihelper.ApiTelegramException: A request to the Telegram API was unsuccessful. Error code: 409. Description: Conflict: terminated by other getUpdates request; make sure that only one bot instance is running

2025-08-09 14:24:48,785 - TeleBot - ERROR - Threaded polling exception: A request to the Telegram API was unsuccessful. Error code: 409. Description: Conflict: terminated by other getUpdates request; make sure that only one bot instance is running
2025-08-09 14:24:48,786 - TeleBot - ERROR - Exception traceback:
Traceback (most recent call last):
  File "/home/spedymax/venv/lib/python3.11/site-packages/telebot/__init__.py", line 1073, in __threaded_polling
    polling_thread.raise_exceptions()
  File "/home/spedymax/venv/lib/python3.11/site-packages/telebot/util.py", line 108, in raise_exceptions
    raise self.exception_info
  File "/home/spedymax/venv/lib/python3.11/site-packages/telebot/util.py", line 90, in run
    task(*args, **kwargs)
  File "/home/spedymax/venv/lib/python3.11/site-packages/telebot/__init__.py", line 649, in __retrieve_updates
    updates = self.get_updates(offset=(self.last_update_id + 1),
             ^^^^^^^^^^^^^^^^^^^^^^^^^^^^^^^^^^^^^^^^^^^^^^^^^^
  File "/home/spedymax/venv/lib/python3.11/site-packages/telebot/__init__.py", line 623, in get_updates
    json_updates = apihelper.get_updates(self.token, offset, limit, timeout, allowed_updates, long_polling_timeout)
                   ^^^^^^^^^^^^^^^^^^^^^^^^^^^^^^^^^^^^^^^^^^^^^^^^^^^^^^^^^^^^^^^^^^^^^^^^^^^^^^^^^^^^^^^^^^^^^^^^
  File "/home/spedymax/venv/lib/python3.11/site-packages/telebot/apihelper.py", line 321, in get_updates
    return _make_request(token, method_url, params=payload)
           ^^^^^^^^^^^^^^^^^^^^^^^^^^^^^^^^^^^^^^^^^^^^^^^^
  File "/home/spedymax/venv/lib/python3.11/site-packages/telebot/apihelper.py", line 162, in _make_request
    json_result = _check_result(method_name, result)
                  ^^^^^^^^^^^^^^^^^^^^^^^^^^^^^^^^^^
  File "/home/spedymax/venv/lib/python3.11/site-packages/telebot/apihelper.py", line 189, in _check_result
    raise ApiTelegramException(method_name, result, result_json)
telebot.apihelper.ApiTelegramException: A request to the Telegram API was unsuccessful. Error code: 409. Description: Conflict: terminated by other getUpdates request; make sure that only one bot instance is running

2025-08-09 14:24:56,837 - TeleBot - ERROR - Threaded polling exception: A request to the Telegram API was unsuccessful. Error code: 409. Description: Conflict: terminated by other getUpdates request; make sure that only one bot instance is running
2025-08-09 14:24:56,838 - TeleBot - ERROR - Exception traceback:
Traceback (most recent call last):
  File "/home/spedymax/venv/lib/python3.11/site-packages/telebot/__init__.py", line 1073, in __threaded_polling
    polling_thread.raise_exceptions()
  File "/home/spedymax/venv/lib/python3.11/site-packages/telebot/util.py", line 108, in raise_exceptions
    raise self.exception_info
  File "/home/spedymax/venv/lib/python3.11/site-packages/telebot/util.py", line 90, in run
    task(*args, **kwargs)
  File "/home/spedymax/venv/lib/python3.11/site-packages/telebot/__init__.py", line 649, in __retrieve_updates
    updates = self.get_updates(offset=(self.last_update_id + 1),
             ^^^^^^^^^^^^^^^^^^^^^^^^^^^^^^^^^^^^^^^^^^^^^^^^^^
  File "/home/spedymax/venv/lib/python3.11/site-packages/telebot/__init__.py", line 623, in get_updates
    json_updates = apihelper.get_updates(self.token, offset, limit, timeout, allowed_updates, long_polling_timeout)
                   ^^^^^^^^^^^^^^^^^^^^^^^^^^^^^^^^^^^^^^^^^^^^^^^^^^^^^^^^^^^^^^^^^^^^^^^^^^^^^^^^^^^^^^^^^^^^^^^^
  File "/home/spedymax/venv/lib/python3.11/site-packages/telebot/apihelper.py", line 321, in get_updates
    return _make_request(token, method_url, params=payload)
           ^^^^^^^^^^^^^^^^^^^^^^^^^^^^^^^^^^^^^^^^^^^^^^^^
  File "/home/spedymax/venv/lib/python3.11/site-packages/telebot/apihelper.py", line 162, in _make_request
    json_result = _check_result(method_name, result)
                  ^^^^^^^^^^^^^^^^^^^^^^^^^^^^^^^^^^
  File "/home/spedymax/venv/lib/python3.11/site-packages/telebot/apihelper.py", line 189, in _check_result
    raise ApiTelegramException(method_name, result, result_json)
telebot.apihelper.ApiTelegramException: A request to the Telegram API was unsuccessful. Error code: 409. Description: Conflict: terminated by other getUpdates request; make sure that only one bot instance is running

2025-08-09 14:25:04,892 - TeleBot - ERROR - Threaded polling exception: A request to the Telegram API was unsuccessful. Error code: 409. Description: Conflict: terminated by other getUpdates request; make sure that only one bot instance is running
2025-08-09 14:25:04,893 - TeleBot - ERROR - Exception traceback:
Traceback (most recent call last):
  File "/home/spedymax/venv/lib/python3.11/site-packages/telebot/__init__.py", line 1073, in __threaded_polling
    polling_thread.raise_exceptions()
  File "/home/spedymax/venv/lib/python3.11/site-packages/telebot/util.py", line 108, in raise_exceptions
    raise self.exception_info
  File "/home/spedymax/venv/lib/python3.11/site-packages/telebot/util.py", line 90, in run
    task(*args, **kwargs)
  File "/home/spedymax/venv/lib/python3.11/site-packages/telebot/__init__.py", line 649, in __retrieve_updates
    updates = self.get_updates(offset=(self.last_update_id + 1),
             ^^^^^^^^^^^^^^^^^^^^^^^^^^^^^^^^^^^^^^^^^^^^^^^^^^
  File "/home/spedymax/venv/lib/python3.11/site-packages/telebot/__init__.py", line 623, in get_updates
    json_updates = apihelper.get_updates(self.token, offset, limit, timeout, allowed_updates, long_polling_timeout)
                   ^^^^^^^^^^^^^^^^^^^^^^^^^^^^^^^^^^^^^^^^^^^^^^^^^^^^^^^^^^^^^^^^^^^^^^^^^^^^^^^^^^^^^^^^^^^^^^^^
  File "/home/spedymax/venv/lib/python3.11/site-packages/telebot/apihelper.py", line 321, in get_updates
    return _make_request(token, method_url, params=payload)
           ^^^^^^^^^^^^^^^^^^^^^^^^^^^^^^^^^^^^^^^^^^^^^^^^
  File "/home/spedymax/venv/lib/python3.11/site-packages/telebot/apihelper.py", line 162, in _make_request
    json_result = _check_result(method_name, result)
                  ^^^^^^^^^^^^^^^^^^^^^^^^^^^^^^^^^^
  File "/home/spedymax/venv/lib/python3.11/site-packages/telebot/apihelper.py", line 189, in _check_result
    raise ApiTelegramException(method_name, result, result_json)
telebot.apihelper.ApiTelegramException: A request to the Telegram API was unsuccessful. Error code: 409. Description: Conflict: terminated by other getUpdates request; make sure that only one bot instance is running

2025-08-09 14:25:20,942 - TeleBot - ERROR - Threaded polling exception: A request to the Telegram API was unsuccessful. Error code: 409. Description: Conflict: terminated by other getUpdates request; make sure that only one bot instance is running
2025-08-09 14:25:20,943 - TeleBot - ERROR - Exception traceback:
Traceback (most recent call last):
  File "/home/spedymax/venv/lib/python3.11/site-packages/telebot/__init__.py", line 1073, in __threaded_polling
    polling_thread.raise_exceptions()
  File "/home/spedymax/venv/lib/python3.11/site-packages/telebot/util.py", line 108, in raise_exceptions
    raise self.exception_info
  File "/home/spedymax/venv/lib/python3.11/site-packages/telebot/util.py", line 90, in run
    task(*args, **kwargs)
  File "/home/spedymax/venv/lib/python3.11/site-packages/telebot/__init__.py", line 649, in __retrieve_updates
    updates = self.get_updates(offset=(self.last_update_id + 1),
             ^^^^^^^^^^^^^^^^^^^^^^^^^^^^^^^^^^^^^^^^^^^^^^^^^^
  File "/home/spedymax/venv/lib/python3.11/site-packages/telebot/__init__.py", line 623, in get_updates
    json_updates = apihelper.get_updates(self.token, offset, limit, timeout, allowed_updates, long_polling_timeout)
                   ^^^^^^^^^^^^^^^^^^^^^^^^^^^^^^^^^^^^^^^^^^^^^^^^^^^^^^^^^^^^^^^^^^^^^^^^^^^^^^^^^^^^^^^^^^^^^^^^
  File "/home/spedymax/venv/lib/python3.11/site-packages/telebot/apihelper.py", line 321, in get_updates
    return _make_request(token, method_url, params=payload)
           ^^^^^^^^^^^^^^^^^^^^^^^^^^^^^^^^^^^^^^^^^^^^^^^^
  File "/home/spedymax/venv/lib/python3.11/site-packages/telebot/apihelper.py", line 162, in _make_request
    json_result = _check_result(method_name, result)
                  ^^^^^^^^^^^^^^^^^^^^^^^^^^^^^^^^^^
  File "/home/spedymax/venv/lib/python3.11/site-packages/telebot/apihelper.py", line 189, in _check_result
    raise ApiTelegramException(method_name, result, result_json)
telebot.apihelper.ApiTelegramException: A request to the Telegram API was unsuccessful. Error code: 409. Description: Conflict: terminated by other getUpdates request; make sure that only one bot instance is running

2025-08-09 14:25:24,296 - TeleBot - ERROR - Threaded polling exception: A request to the Telegram API was unsuccessful. Error code: 409. Description: Conflict: terminated by other getUpdates request; make sure that only one bot instance is running
2025-08-09 14:25:24,297 - TeleBot - ERROR - Exception traceback:
Traceback (most recent call last):
  File "/home/spedymax/venv/lib/python3.11/site-packages/telebot/__init__.py", line 1073, in __threaded_polling
    polling_thread.raise_exceptions()
  File "/home/spedymax/venv/lib/python3.11/site-packages/telebot/util.py", line 108, in raise_exceptions
    raise self.exception_info
  File "/home/spedymax/venv/lib/python3.11/site-packages/telebot/util.py", line 90, in run
    task(*args, **kwargs)
  File "/home/spedymax/venv/lib/python3.11/site-packages/telebot/__init__.py", line 649, in __retrieve_updates
    updates = self.get_updates(offset=(self.last_update_id + 1),
             ^^^^^^^^^^^^^^^^^^^^^^^^^^^^^^^^^^^^^^^^^^^^^^^^^^
  File "/home/spedymax/venv/lib/python3.11/site-packages/telebot/__init__.py", line 623, in get_updates
    json_updates = apihelper.get_updates(self.token, offset, limit, timeout, allowed_updates, long_polling_timeout)
                   ^^^^^^^^^^^^^^^^^^^^^^^^^^^^^^^^^^^^^^^^^^^^^^^^^^^^^^^^^^^^^^^^^^^^^^^^^^^^^^^^^^^^^^^^^^^^^^^^
  File "/home/spedymax/venv/lib/python3.11/site-packages/telebot/apihelper.py", line 321, in get_updates
    return _make_request(token, method_url, params=payload)
           ^^^^^^^^^^^^^^^^^^^^^^^^^^^^^^^^^^^^^^^^^^^^^^^^
  File "/home/spedymax/venv/lib/python3.11/site-packages/telebot/apihelper.py", line 162, in _make_request
    json_result = _check_result(method_name, result)
                  ^^^^^^^^^^^^^^^^^^^^^^^^^^^^^^^^^^
  File "/home/spedymax/venv/lib/python3.11/site-packages/telebot/apihelper.py", line 189, in _check_result
    raise ApiTelegramException(method_name, result, result_json)
telebot.apihelper.ApiTelegramException: A request to the Telegram API was unsuccessful. Error code: 409. Description: Conflict: terminated by other getUpdates request; make sure that only one bot instance is running

2025-08-09 14:25:56,346 - TeleBot - ERROR - Threaded polling exception: A request to the Telegram API was unsuccessful. Error code: 409. Description: Conflict: terminated by other getUpdates request; make sure that only one bot instance is running
2025-08-09 14:25:56,348 - TeleBot - ERROR - Exception traceback:
Traceback (most recent call last):
  File "/home/spedymax/venv/lib/python3.11/site-packages/telebot/__init__.py", line 1073, in __threaded_polling
    polling_thread.raise_exceptions()
  File "/home/spedymax/venv/lib/python3.11/site-packages/telebot/util.py", line 108, in raise_exceptions
    raise self.exception_info
  File "/home/spedymax/venv/lib/python3.11/site-packages/telebot/util.py", line 90, in run
    task(*args, **kwargs)
  File "/home/spedymax/venv/lib/python3.11/site-packages/telebot/__init__.py", line 649, in __retrieve_updates
    updates = self.get_updates(offset=(self.last_update_id + 1),
             ^^^^^^^^^^^^^^^^^^^^^^^^^^^^^^^^^^^^^^^^^^^^^^^^^^
  File "/home/spedymax/venv/lib/python3.11/site-packages/telebot/__init__.py", line 623, in get_updates
    json_updates = apihelper.get_updates(self.token, offset, limit, timeout, allowed_updates, long_polling_timeout)
                   ^^^^^^^^^^^^^^^^^^^^^^^^^^^^^^^^^^^^^^^^^^^^^^^^^^^^^^^^^^^^^^^^^^^^^^^^^^^^^^^^^^^^^^^^^^^^^^^^
  File "/home/spedymax/venv/lib/python3.11/site-packages/telebot/apihelper.py", line 321, in get_updates
    return _make_request(token, method_url, params=payload)
           ^^^^^^^^^^^^^^^^^^^^^^^^^^^^^^^^^^^^^^^^^^^^^^^^
  File "/home/spedymax/venv/lib/python3.11/site-packages/telebot/apihelper.py", line 162, in _make_request
    json_result = _check_result(method_name, result)
                  ^^^^^^^^^^^^^^^^^^^^^^^^^^^^^^^^^^
  File "/home/spedymax/venv/lib/python3.11/site-packages/telebot/apihelper.py", line 189, in _check_result
    raise ApiTelegramException(method_name, result, result_json)
telebot.apihelper.ApiTelegramException: A request to the Telegram API was unsuccessful. Error code: 409. Description: Conflict: terminated by other getUpdates request; make sure that only one bot instance is running

2025-08-09 14:25:59,648 - TeleBot - ERROR - Threaded polling exception: A request to the Telegram API was unsuccessful. Error code: 409. Description: Conflict: terminated by other getUpdates request; make sure that only one bot instance is running
2025-08-09 14:25:59,650 - TeleBot - ERROR - Exception traceback:
Traceback (most recent call last):
  File "/home/spedymax/venv/lib/python3.11/site-packages/telebot/__init__.py", line 1073, in __threaded_polling
    polling_thread.raise_exceptions()
  File "/home/spedymax/venv/lib/python3.11/site-packages/telebot/util.py", line 108, in raise_exceptions
    raise self.exception_info
  File "/home/spedymax/venv/lib/python3.11/site-packages/telebot/util.py", line 90, in run
    task(*args, **kwargs)
  File "/home/spedymax/venv/lib/python3.11/site-packages/telebot/__init__.py", line 649, in __retrieve_updates
    updates = self.get_updates(offset=(self.last_update_id + 1),
             ^^^^^^^^^^^^^^^^^^^^^^^^^^^^^^^^^^^^^^^^^^^^^^^^^^
  File "/home/spedymax/venv/lib/python3.11/site-packages/telebot/__init__.py", line 623, in get_updates
    json_updates = apihelper.get_updates(self.token, offset, limit, timeout, allowed_updates, long_polling_timeout)
                   ^^^^^^^^^^^^^^^^^^^^^^^^^^^^^^^^^^^^^^^^^^^^^^^^^^^^^^^^^^^^^^^^^^^^^^^^^^^^^^^^^^^^^^^^^^^^^^^^
  File "/home/spedymax/venv/lib/python3.11/site-packages/telebot/apihelper.py", line 321, in get_updates
    return _make_request(token, method_url, params=payload)
           ^^^^^^^^^^^^^^^^^^^^^^^^^^^^^^^^^^^^^^^^^^^^^^^^
  File "/home/spedymax/venv/lib/python3.11/site-packages/telebot/apihelper.py", line 162, in _make_request
    json_result = _check_result(method_name, result)
                  ^^^^^^^^^^^^^^^^^^^^^^^^^^^^^^^^^^
  File "/home/spedymax/venv/lib/python3.11/site-packages/telebot/apihelper.py", line 189, in _check_result
    raise ApiTelegramException(method_name, result, result_json)
telebot.apihelper.ApiTelegramException: A request to the Telegram API was unsuccessful. Error code: 409. Description: Conflict: terminated by other getUpdates request; make sure that only one bot instance is running

2025-08-09 14:26:09,980 - __main__ - INFO - Bot stopped by user
2025-08-09 14:26:09,980 - __main__ - INFO - Stopping quiz scheduler...
2025-08-09 14:26:14,980 - services.quiz_scheduler - INFO - Quiz scheduler stopped
2025-08-09 14:26:14,981 - __main__ - INFO - Database connections closed
